Workbook

Sheet Resumen
B2: EVOLTI · INFORME DE COMPRAS
B3: PROYECTO POLARIS 4 — MINIGRANJAS
B4: Tipo de proyecto: Mini Granjas · Exportación de órdenes de compra
B5: Periodo: 2025-10-01 a 2026-08-25 · Generado: 2026-09-21 · Moneda: COP · Cifras calculadas con fórmulas sobre la hoja Detalle
B7: TOTALES DEL PROYECTO
B8: VALOR TOTAL (sin IVA) | D8: =SUM(Detalle!$K$2:$K$326)
B9: IVA | D9: =SUM(Detalle!$M$2:$M$326)
B10: TOTAL CON IVA | D10: =SUM(Detalle!$K$2:$K$326)+SUM(Detalle!$M$2:$M$326)
B12: INDICADORES
B13: Órdenes de compra (No OC únicas) | D13: 106
B14: Líneas de ítem / compras | D14: =COUNTA(Detalle!$K$2:$K$326)
B15: Proveedores distintos | D15: 33
B16: Categorías (Grupos) | D16: 15
B18: GASTO DE OBRA vs ADMINISTRATIVO
B19: Concepto | C19: Valor sin IVA | D19: IVA | E19: Total con IVA
B20: Gasto de obra | C20: =SUMIFS(Detalle!$K$2:$K$326,Detalle!$R$2:$R$326,"<>ADMINISTRATIVO") | D20: =SUMIFS(Detalle!$M$2:$M$326,Detalle!$R$2:$R$326,"<>ADMINISTRATIVO") | E20: =C20+D20
B21: Gasto administrativo | C21: =SUMIFS(Detalle!$K$2:$K$326,Detalle!$R$2:$R$326,"ADMINISTRATIVO") | D21: =SUMIFS(Detalle!$M$2:$M$326,Detalle!$R$2:$R$326,"ADMINISTRATIVO") | E21: =C21+D21
B22: TOTAL | C22: =SUM(C20:C21) | D22: =SUM(D20:D21) | E22: =C22+D22

Sheet Por categoría
B2: GASTO POR CATEGORÍA (GRUPO Y SUBGRUPO)
B3: Cada grupo se abre en sus subgrupos. Los valores son fórmulas SUMAR.SI.CONJUNTO sobre la hoja Detalle.
B5: Grupo | C5: Subgrupo | D5: Valor sin IVA | E5: IVA | F5: Total con IVA | G5: % del total | I5: _grupo | J5: _valor
B6: Servicio | D6: =SUMIFS(Detalle!$K$2:$K$326,Detalle!$F$2:$F$326,$B6) | E6: =SUMIFS(Detalle!$M$2:$M$326,Detalle!$F$2:$F$326,$B6) | F6: =D6+E6 | G6: =IF(SUM(Detalle!$K$2:$K$326)=0,0,D6/SUM(Detalle!$K$2:$K$326)) | I6: =B6 | J6: =D6
C7: Cerramiento Perimetral | D7: =SUMIFS(Detalle!$K$2:$K$326,Detalle!$F$2:$F$326,$B6,Detalle!$G$2:$G$326,$C7) | E7: =SUMIFS(Detalle!$M$2:$M$326,Detalle!$F$2:$F$326,$B6,Detalle!$G$2:$G$326,$C7) | F7: =D7+E7 | G7: =IF(SUM(Detalle!$K$2:$K$326)=0,0,D7/SUM(Detalle!$K$2:$K$326)) | I7: =B18 | J7: =D18
C8: Preparativos Previos Inicio De Obras | D8: =SUMIFS(Detalle!$K$2:$K$326,Detalle!$F$2:$F$326,$B6,Detalle!$G$2:$G$326,$C8) | E8: =SUMIFS(Detalle!$M$2:$M$326,Detalle!$F$2:$F$326,$B6,Detalle!$G$2:$G$326,$C8) | F8: =D8+E8 | G8: =IF(SUM(Detalle!$K$2:$K$326)=0,0,D8/SUM(Detalle!$K$2:$K$326)) | I8: =B20 | J8: =D20
C9: Set (Electrico)Servicio | D9: =SUMIFS(Detalle!$K$2:$K$326,Detalle!$F$2:$F$326,$B6,Detalle!$G$2:$G$326,$C9) | E9: =SUMIFS(Detalle!$M$2:$M$326,Detalle!$F$2:$F$326,$B6,Detalle!$G$2:$G$326,$C9) | F9: =D9+E9 | G9: =IF(SUM(Detalle!$K$2:$K$326)=0,0,D9/SUM(Detalle!$K$2:$K$326)) | I9: =B23 | J9: =D23
C10: Logística Viáticos | D10: =SUMIFS(Detalle!$K$2:$K$326,Detalle!$F$2:$F$326,$B6,Detalle!$G$2:$G$326,$C10) | E10: =SUMIFS(Detalle!$M$2:$M$326,Detalle!$F$2:$F$326,$B6,Detalle!$G$2:$G$326,$C10) | F10: =D10+E10 | G10: =IF(SUM(Detalle!$K$2:$K$326)=0,0,D10/SUM(Detalle!$K$2:$K$326)) | I10: =B25 | J10: =D25
C11: Set (Civil) Servicio | D11: =SUMIFS(Detalle!$K$2:$K$326,Detalle!$F$2:$F$326,$B6,Detalle!$G$2:$G$326,$C11) | E11: =SUMIFS(Detalle!$M$2:$M$326,Detalle!$F$2:$F$326,$B6,Detalle!$G$2:$G$326,$C11) | F11: =D11+E11 | G11: =IF(SUM(Detalle!$K$2:$K$326)=0,0,D11/SUM(Detalle!$K$2:$K$326)) | I11: =B27 | J11: =D27
C12: Descargues | D12: =SUMIFS(Detalle!$K$2:$K$326,Detalle!$F$2:$F$326,$B6,Detalle!$G$2:$G$326,$C12) | E12: =SUMIFS(Detalle!$M$2:$M$326,Detalle!$F$2:$F$326,$B6,Detalle!$G$2:$G$326,$C12) | F12: =D12+E12 | G12: =IF(SUM(Detalle!$K$2:$K$326)=0,0,D12/SUM(Detalle!$K$2:$K$326)) | I12: =B30 | J12: =D30
C13: Baños Portátiles | D13: =SUMIFS(Detalle!$K$2:$K$326,Detalle!$F$2:$F$326,$B6,Detalle!$G$2:$G$326,$C13) | E13: =SUMIFS(Detalle!$M$2:$M$326,Detalle!$F$2:$F$326,$B6,Detalle!$G$2:$G$326,$C13) | F13: =D13+E13 | G13: =IF(SUM(Detalle!$K$2:$K$326)=0,0,D13/SUM(Detalle!$K$2:$K$326)) | I13: =B33 | J13: =D33
C14: Upme | D14: =SUMIFS(Detalle!$K$2:$K$326,Detalle!$F$2:$F$326,$B6,Detalle!$G$2:$G$326,$C14) | E14: =SUMIFS(Detalle!$M$2:$M$326,Detalle!$F$2:$F$326,$B6,Detalle!$G$2:$G$326,$C14) | F14: =D14+E14 | G14: =IF(SUM(Detalle!$K$2:$K$326)=0,0,D14/SUM(Detalle!$K$2:$K$326)) | I14: =B36 | J14: =D36
C15: Transportes | D15: =SUMIFS(Detalle!$K$2:$K$326,Detalle!$F$2:$F$326,$B6,Detalle!$G$2:$G$326,$C15) | E15: =SUMIFS(Detalle!$M$2:$M$326,Detalle!$F$2:$F$326,$B6,Detalle!$G$2:$G$326,$C15) | F15: =D15+E15 | G15: =IF(SUM(Detalle!$K$2:$K$326)=0,0,D15/SUM(Detalle!$K$2:$K$326)) | I15: =B38 | J15: =D38
C16: Retie | D16: =SUMIFS(Detalle!$K$2:$K$326,Detalle!$F$2:$F$326,$B6,Detalle!$G$2:$G$326,$C16) | E16: =SUMIFS(Detalle!$M$2:$M$326,Detalle!$F$2:$F$326,$B6,Detalle!$G$2:$G$326,$C16) | F16: =D16+E16 | G16: =IF(SUM(Detalle!$K$2:$K$326)=0,0,D16/SUM(Detalle!$K$2:$K$326)) | I16: =B41 | J16: =D41
C17: (Sin Subgrupo) | D17: =SUMIFS(Detalle!$K$2:$K$326,Detalle!$F$2:$F$326,$B6,Detalle!$G$2:$G$326,$C17) | E17: =SUMIFS(Detalle!$M$2:$M$326,Detalle!$F$2:$F$326,$B6,Detalle!$G$2:$G$326,$C17) | F17: =D17+E17 | G17: =IF(SUM(Detalle!$K$2:$K$326)=0,0,D17/SUM(Detalle!$K$2:$K$326)) | I17: =B43 | J17: =D43
B18: C. Estructura Solar | D18: =SUMIFS(Detalle!$K$2:$K$326,Detalle!$F$2:$F$326,$B18) | E18: =SUMIFS(Detalle!$M$2:$M$326,Detalle!$F$2:$F$326,$B18) | F18: =D18+E18 | G18: =IF(SUM(Detalle!$K$2:$K$326)=0,0,D18/SUM(Detalle!$K$2:$K$326)) | I18: =B45 | J18: =D45
C19: (Sin Subgrupo) | D19: =SUMIFS(Detalle!$K$2:$K$326,Detalle!$F$2:$F$326,$B18,Detalle!$G$2:$G$326,$C19) | E19: =SUMIFS(Detalle!$M$2:$M$326,Detalle!$F$2:$F$326,$B18,Detalle!$G$2:$G$326,$C19) | F19: =D19+E19 | G19: =IF(SUM(Detalle!$K$2:$K$326)=0,0,D19/SUM(Detalle!$K$2:$K$326)) | I19: =B47 | J19: =D47
B20: Set (Electrico) Suministro | D20: =SUMIFS(Detalle!$K$2:$K$326,Detalle!$F$2:$F$326,$B20) | E20: =SUMIFS(Detalle!$M$2:$M$326,Detalle!$F$2:$F$326,$B20) | F20: =D20+E20 | G20: =IF(SUM(Detalle!$K$2:$K$326)=0,0,D20/SUM(Detalle!$K$2:$K$326)) | I20: =B49 | J20: =D49
C21: (Sin Subgrupo) | D21: =SUMIFS(Detalle!$K$2:$K$326,Detalle!$F$2:$F$326,$B20,Detalle!$G$2:$G$326,$C21) | E21: =SUMIFS(Detalle!$M$2:$M$326,Detalle!$F$2:$F$326,$B20,Detalle!$G$2:$G$326,$C21) | F21: =D21+E21 | G21: =IF(SUM(Detalle!$K$2:$K$326)=0,0,D21/SUM(Detalle!$K$2:$K$326))
C22: Set (Electrico)Servicio | D22: =SUMIFS(Detalle!$K$2:$K$326,Detalle!$F$2:$F$326,$B20,Detalle!$G$2:$G$326,$C22) | E22: =SUMIFS(Detalle!$M$2:$M$326,Detalle!$F$2:$F$326,$B20,Detalle!$G$2:$G$326,$C22) | F22: =D22+E22 | G22: =IF(SUM(Detalle!$K$2:$K$326)=0,0,D22/SUM(Detalle!$K$2:$K$326))
B23: C. Inversores | D23: =SUMIFS(Detalle!$K$2:$K$326,Detalle!$F$2:$F$326,$B23) | E23: =SUMIFS(Detalle!$M$2:$M$326,Detalle!$F$2:$F$326,$B23) | F23: =D23+E23 | G23: =IF(SUM(Detalle!$K$2:$K$326)=0,0,D23/SUM(Detalle!$K$2:$K$326))
C24: (Sin Subgrupo) | D24: =SUMIFS(Detalle!$K$2:$K$326,Detalle!$F$2:$F$326,$B23,Detalle!$G$2:$G$326,$C24) | E24: =SUMIFS(Detalle!$M$2:$M$326,Detalle!$F$2:$F$326,$B23,Detalle!$G$2:$G$326,$C24) | F24: =D24+E24 | G24: =IF(SUM(Detalle!$K$2:$K$326)=0,0,D24/SUM(Detalle!$K$2:$K$326))
B25: C. Material Micropilotaje | D25: =SUMIFS(Detalle!$K$2:$K$326,Detalle!$F$2:$F$326,$B25) | E25: =SUMIFS(Detalle!$M$2:$M$326,Detalle!$F$2:$F$326,$B25) | F25: =D25+E25 | G25: =IF(SUM(Detalle!$K$2:$K$326)=0,0,D25/SUM(Detalle!$K$2:$K$326))
C26: (Sin Subgrupo) | D26: =SUMIFS(Detalle!$K$2:$K$326,Detalle!$F$2:$F$326,$B25,Detalle!$G$2:$G$326,$C26) | E26: =SUMIFS(Detalle!$M$2:$M$326,Detalle!$F$2:$F$326,$B25,Detalle!$G$2:$G$326,$C26) | F26: =D26+E26 | G26: =IF(SUM(Detalle!$K$2:$K$326)=0,0,D26/SUM(Detalle!$K$2:$K$326))
B27: Set (Civil) Suministro | D27: =SUMIFS(Detalle!$K$2:$K$326,Detalle!$F$2:$F$326,$B27) | E27: =SUMIFS(Detalle!$M$2:$M$326,Detalle!$F$2:$F$326,$B27) | F27: =D27+E27 | G27: =IF(SUM(Detalle!$K$2:$K$326)=0,0,D27/SUM(Detalle!$K$2:$K$326))
C28: Set (Civil) Servicio | D28: =SUMIFS(Detalle!$K$2:$K$326,Detalle!$F$2:$F$326,$B27,Detalle!$G$2:$G$326,$C28) | E28: =SUMIFS(Detalle!$M$2:$M$326,Detalle!$F$2:$F$326,$B27,Detalle!$G$2:$G$326,$C28) | F28: =D28+E28 | G28: =IF(SUM(Detalle!$K$2:$K$326)=0,0,D28/SUM(Detalle!$K$2:$K$326))
C29: (Sin Subgrupo) | D29: =SUMIFS(Detalle!$K$2:$K$326,Detalle!$F$2:$F$326,$B27,Detalle!$G$2:$G$326,$C29) | E29: =SUMIFS(Detalle!$M$2:$M$326,Detalle!$F$2:$F$326,$B27,Detalle!$G$2:$G$326,$C29) | F29: =D29+E29 | G29: =IF(SUM(Detalle!$K$2:$K$326)=0,0,D29/SUM(Detalle!$K$2:$K$326))
B30: Cajas De Paso | D30: =SUMIFS(Detalle!$K$2:$K$326,Detalle!$F$2:$F$326,$B30) | E30: =SUMIFS(Detalle!$M$2:$M$326,Detalle!$F$2:$F$326,$B30) | F30: =D30+E30 | G30: =IF(SUM(Detalle!$K$2:$K$326)=0,0,D30/SUM(Detalle!$K$2:$K$326))
C31: (Sin Subgrupo) | D31: =SUMIFS(Detalle!$K$2:$K$326,Detalle!$F$2:$F$326,$B30,Detalle!$G$2:$G$326,$C31) | E31: =SUMIFS(Detalle!$M$2:$M$326,Detalle!$F$2:$F$326,$B30,Detalle!$G$2:$G$326,$C31) | F31: =D31+E31 | G31: =IF(SUM(Detalle!$K$2:$K$326)=0,0,D31/SUM(Detalle!$K$2:$K$326))
C32: Transportes | D32: =SUMIFS(Detalle!$K$2:$K$326,Detalle!$F$2:$F$326,$B30,Detalle!$G$2:$G$326,$C32) | E32: =SUMIFS(Detalle!$M$2:$M$326,Detalle!$F$2:$F$326,$B30,Detalle!$G$2:$G$326,$C32) | F32: =D32+E32 | G32: =IF(SUM(Detalle!$K$2:$K$326)=0,0,D32/SUM(Detalle!$K$2:$K$326))
B33: Montaje Eléctrico | D33: =SUMIFS(Detalle!$K$2:$K$326,Detalle!$F$2:$F$326,$B33) | E33: =SUMIFS(Detalle!$M$2:$M$326,Detalle!$F$2:$F$326,$B33) | F33: =D33+E33 | G33: =IF(SUM(Detalle!$K$2:$K$326)=0,0,D33/SUM(Detalle!$K$2:$K$326))
C34: Set (Electrico)Servicio | D34: =SUMIFS(Detalle!$K$2:$K$326,Detalle!$F$2:$F$326,$B33,Detalle!$G$2:$G$326,$C34) | E34: =SUMIFS(Detalle!$M$2:$M$326,Detalle!$F$2:$F$326,$B33,Detalle!$G$2:$G$326,$C34) | F34: =D34+E34 | G34: =IF(SUM(Detalle!$K$2:$K$326)=0,0,D34/SUM(Detalle!$K$2:$K$326))
C35: (Sin Subgrupo) | D35: =SUMIFS(Detalle!$K$2:$K$326,Detalle!$F$2:$F$326,$B33,Detalle!$G$2:$G$326,$C35) | E35: =SUMIFS(Detalle!$M$2:$M$326,Detalle!$F$2:$F$326,$B33,Detalle!$G$2:$G$326,$C35) | F35: =D35+E35 | G35: =IF(SUM(Detalle!$K$2:$K$326)=0,0,D35/SUM(Detalle!$K$2:$K$326))
B36: Gastos Administrativos | D36: =SUMIFS(Detalle!$K$2:$K$326,Detalle!$F$2:$F$326,$B36) | E36: =SUMIFS(Detalle!$M$2:$M$326,Detalle!$F$2:$F$326,$B36) | F36: =D36+E36 | G36: =IF(SUM(Detalle!$K$2:$K$326)=0,0,D36/SUM(Detalle!$K$2:$K$326))
C37: Logística Viáticos | D37: =SUMIFS(Detalle!$K$2:$K$326,Detalle!$F$2:$F$326,$B36,Detalle!$G$2:$G$326,$C37) | E37: =SUMIFS(Detalle!$M$2:$M$326,Detalle!$F$2:$F$326,$B36,Detalle!$G$2:$G$326,$C37) | F37: =D37+E37 | G37: =IF(SUM(Detalle!$K$2:$K$326)=0,0,D37/SUM(Detalle!$K$2:$K$326))
B38: C. Canalizaciones | D38: =SUMIFS(Detalle!$K$2:$K$326,Detalle!$F$2:$F$326,$B38) | E38: =SUMIFS(Detalle!$M$2:$M$326,Detalle!$F$2:$F$326,$B38) | F38: =D38+E38 | G38: =IF(SUM(Detalle!$K$2:$K$326)=0,0,D38/SUM(Detalle!$K$2:$K$326))
C39: (Sin Subgrupo) | D39: =SUMIFS(Detalle!$K$2:$K$326,Detalle!$F$2:$F$326,$B38,Detalle!$G$2:$G$326,$C39) | E39: =SUMIFS(Detalle!$M$2:$M$326,Detalle!$F$2:$F$326,$B38,Detalle!$G$2:$G$326,$C39) | F39: =D39+E39 | G39: =IF(SUM(Detalle!$K$2:$K$326)=0,0,D39/SUM(Detalle!$K$2:$K$326))
C40: Instalación De Tuberías Ac, Dc Y Tierra | D40: =SUMIFS(Detalle!$K$2:$K$326,Detalle!$F$2:$F$326,$B38,Detalle!$G$2:$G$326,$C40) | E40: =SUMIFS(Detalle!$M$2:$M$326,Detalle!$F$2:$F$326,$B38,Detalle!$G$2:$G$326,$C40) | F40: =D40+E40 | G40: =IF(SUM(Detalle!$K$2:$K$326)=0,0,D40/SUM(Detalle!$K$2:$K$326))
B41: Armado Mesas Fv | D41: =SUMIFS(Detalle!$K$2:$K$326,Detalle!$F$2:$F$326,$B41) | E41: =SUMIFS(Detalle!$M$2:$M$326,Detalle!$F$2:$F$326,$B41) | F41: =D41+E41 | G41: =IF(SUM(Detalle!$K$2:$K$326)=0,0,D41/SUM(Detalle!$K$2:$K$326))
C42: (Sin Subgrupo) | D42: =SUMIFS(Detalle!$K$2:$K$326,Detalle!$F$2:$F$326,$B41,Detalle!$G$2:$G$326,$C42) | E42: =SUMIFS(Detalle!$M$2:$M$326,Detalle!$F$2:$F$326,$B41,Detalle!$G$2:$G$326,$C42) | F42: =D42+E42 | G42: =IF(SUM(Detalle!$K$2:$K$326)=0,0,D42/SUM(Detalle!$K$2:$K$326))
...

Sheet Por tipo de ítem
B2: ¿QUÉ SE COMPRÓ? — CATEGORIZACIÓN DE ÍTEMS
B3: Los ítems se agrupan por tipo (transformadores, medidores, inversores, cable, etc.). Se muestra la cantidad total y el valor. Cantidades y valores son fórmulas sobre la hoja Detalle.
B5: RESUMEN POR CATEGORÍA
B6: Categoría de ítem | C6: Cant. total | D6: Valor sin IVA | E6: IVA | F6: Total con IVA | G6: % del total
B7: Estructura y soportería solar | C7: =SUMIFS(Detalle!$I$2:$I$326,Detalle!$T$2:$T$326,$B7) | D7: =SUMIFS(Detalle!$K$2:$K$326,Detalle!$T$2:$T$326,$B7) | E7: =SUMIFS(Detalle!$M$2:$M$326,Detalle!$T$2:$T$326,$B7) | F7: =D7+E7 | G7: =IF(SUM(Detalle!$K$2:$K$326)=0,0,D7/SUM(Detalle!$K$2:$K$326))
B8: Cerramiento perimetral | C8: =SUMIFS(Detalle!$I$2:$I$326,Detalle!$T$2:$T$326,$B8) | D8: =SUMIFS(Detalle!$K$2:$K$326,Detalle!$T$2:$T$326,$B8) | E8: =SUMIFS(Detalle!$M$2:$M$326,Detalle!$T$2:$T$326,$B8) | F8: =D8+E8 | G8: =IF(SUM(Detalle!$K$2:$K$326)=0,0,D8/SUM(Detalle!$K$2:$K$326))
B9: Obra civil (concreto, agregados) | C9: =SUMIFS(Detalle!$I$2:$I$326,Detalle!$T$2:$T$326,$B9) | D9: =SUMIFS(Detalle!$K$2:$K$326,Detalle!$T$2:$T$326,$B9) | E9: =SUMIFS(Detalle!$M$2:$M$326,Detalle!$T$2:$T$326,$B9) | F9: =D9+E9 | G9: =IF(SUM(Detalle!$K$2:$K$326)=0,0,D9/SUM(Detalle!$K$2:$K$326))
B10: Inversores | C10: =SUMIFS(Detalle!$I$2:$I$326,Detalle!$T$2:$T$326,$B10) | D10: =SUMIFS(Detalle!$K$2:$K$326,Detalle!$T$2:$T$326,$B10) | E10: =SUMIFS(Detalle!$M$2:$M$326,Detalle!$T$2:$T$326,$B10) | F10: =D10+E10 | G10: =IF(SUM(Detalle!$K$2:$K$326)=0,0,D10/SUM(Detalle!$K$2:$K$326))
B11: Cableado y conductores | C11: =SUMIFS(Detalle!$I$2:$I$326,Detalle!$T$2:$T$326,$B11) | D11: =SUMIFS(Detalle!$K$2:$K$326,Detalle!$T$2:$T$326,$B11) | E11: =SUMIFS(Detalle!$M$2:$M$326,Detalle!$T$2:$T$326,$B11) | F11: =D11+E11 | G11: =IF(SUM(Detalle!$K$2:$K$326)=0,0,D11/SUM(Detalle!$K$2:$K$326))
B12: Servicios de obra e ingeniería | C12: =SUMIFS(Detalle!$I$2:$I$326,Detalle!$T$2:$T$326,$B12) | D12: =SUMIFS(Detalle!$K$2:$K$326,Detalle!$T$2:$T$326,$B12) | E12: =SUMIFS(Detalle!$M$2:$M$326,Detalle!$T$2:$T$326,$B12) | F12: =D12+E12 | G12: =IF(SUM(Detalle!$K$2:$K$326)=0,0,D12/SUM(Detalle!$K$2:$K$326))
B13: Alquiler de maquinaria y equipos | C13: =SUMIFS(Detalle!$I$2:$I$326,Detalle!$T$2:$T$326,$B13) | D13: =SUMIFS(Detalle!$K$2:$K$326,Detalle!$T$2:$T$326,$B13) | E13: =SUMIFS(Detalle!$M$2:$M$326,Detalle!$T$2:$T$326,$B13) | F13: =D13+E13 | G13: =IF(SUM(Detalle!$K$2:$K$326)=0,0,D13/SUM(Detalle!$K$2:$K$326))
B14: RETIE / Legalización / Medición | C14: =SUMIFS(Detalle!$I$2:$I$326,Detalle!$T$2:$T$326,$B14) | D14: =SUMIFS(Detalle!$K$2:$K$326,Detalle!$T$2:$T$326,$B14) | E14: =SUMIFS(Detalle!$M$2:$M$326,Detalle!$T$2:$T$326,$B14) | F14: =D14+E14 | G14: =IF(SUM(Detalle!$K$2:$K$326)=0,0,D14/SUM(Detalle!$K$2:$K$326))
B15: Viáticos - Alimentación | C15: =SUMIFS(Detalle!$I$2:$I$326,Detalle!$T$2:$T$326,$B15) | D15: =SUMIFS(Detalle!$K$2:$K$326,Detalle!$T$2:$T$326,$B15) | E15: =SUMIFS(Detalle!$M$2:$M$326,Detalle!$T$2:$T$326,$B15) | F15: =D15+E15 | G15: =IF(SUM(Detalle!$K$2:$K$326)=0,0,D15/SUM(Detalle!$K$2:$K$326))
B16: Fletes y transporte de carga | C16: =SUMIFS(Detalle!$I$2:$I$326,Detalle!$T$2:$T$326,$B16) | D16: =SUMIFS(Detalle!$K$2:$K$326,Detalle!$T$2:$T$326,$B16) | E16: =SUMIFS(Detalle!$M$2:$M$326,Detalle!$T$2:$T$326,$B16) | F16: =D16+E16 | G16: =IF(SUM(Detalle!$K$2:$K$326)=0,0,D16/SUM(Detalle!$K$2:$K$326))
B17: Viáticos - Hospedaje | C17: =SUMIFS(Detalle!$I$2:$I$326,Detalle!$T$2:$T$326,$B17) | D17: =SUMIFS(Detalle!$K$2:$K$326,Detalle!$T$2:$T$326,$B17) | E17: =SUMIFS(Detalle!$M$2:$M$326,Detalle!$T$2:$T$326,$B17) | F17: =D17+E17 | G17: =IF(SUM(Detalle!$K$2:$K$326)=0,0,D17/SUM(Detalle!$K$2:$K$326))
B18: Canalización y tubería | C18: =SUMIFS(Detalle!$I$2:$I$326,Detalle!$T$2:$T$326,$B18) | D18: =SUMIFS(Detalle!$K$2:$K$326,Detalle!$T$2:$T$326,$B18) | E18: =SUMIFS(Detalle!$M$2:$M$326,Detalle!$T$2:$T$326,$B18) | F18: =D18+E18 | G18: =IF(SUM(Detalle!$K$2:$K$326)=0,0,D18/SUM(Detalle!$K$2:$K$326))
... B32: Tableros y protecciones | C32: =SUMIFS(Detalle!$I$2:$I$326,Detalle!$T$2:$T$326,$B32) | D32: =SUMIFS(Detalle!$K$2:$K$326,Detalle!$T$2:$T$326,$B32) | E32: =SUMIFS(Detalle!$M$2:$M$326,Detalle!$T$2:$T$326,$B32) | F32: =D32+E32 | G32: =IF(SUM(Detalle!$K$2:$K$326)=0,0,D32/SUM(Detalle!$K$2:$K$326))
B33: TOTAL | C33: =SUM(C7:C32) | D33: =SUM(Detalle!$K$2:$K$326) | E33: =SUM(Detalle!$M$2:$M$326) | F33: =D33+E33 | G33: 1
B36: DETALLE DE ÍTEMS POR CATEGORÍA
B37: Aquí se ve, por ejemplo, cuántos transformadores, medidores o inversores consumió el proyecto.
B38: Categoría / Ítem | C38: Cant. | D38: Valor sin IVA | E38: IVA | F38: Total con IVA
B39: Estructura y soportería solar | C39: =SUMIFS(Detalle!$I$2:$I$326,Detalle!$T$2:$T$326,$B39) | D39: =SUMIFS(Detalle!$K$2:$K$326,Detalle!$T$2:$T$326,$B39) | E39: =SUMIFS(Detalle!$M$2:$M$326,Detalle!$T$2:$T$326,$B39) | F39: =D39+E39
B40: ESTRUCTURA SOLAR TIPO GRANJA - TIPO DE MESA 2PV14 PARA 28 PANELES - UND | C40: =SUMIFS(Detalle!$I$2:$I$326,Detalle!$T$2:$T$326,$B39,Detalle!$H$2:$H$326,$B40) | D40: =SUMIFS(Detalle!$K$2:$K$326,Detalle!$T$2:$T$326,$B39,Detalle!$H$2:$H$326,$B40) | E40: =SUMIFS(Detalle!$M$2:$M$326,Detalle!$T$2:$T$326,$B39,Detalle!$H$2:$H$326,$B40) | F40: =D40+E40
B41: SUMINISTRO DE ESTRUCTURA METALICA PARA TECHO SUBESTACION. MATERIALES: 6 COLUMNAS EN TUBO CUADRADO 100 X 100 EN 4MM, 3 VIGAS EN TUBO RECTANGULAR DE 100 X 50 EN 2 MM, CORREAS EN PHR 120 X 60 EN 1.5 MM, RIDIGIZADORES EN PLATINA DE 3/4 X 3 /16, CANAL EN - UND | C41: =SUMIFS(Detalle!$I$2:$I$326,Detalle!$T$2:$T$326,$B39,Detalle!$H$2:$H$326,$B41) | D41: =SUMIFS(Detalle!$K$2:$K$326,Detalle!$T$2:$T$326,$B39,Detalle!$H$2:$H$326,$B41) | E41: =SUMIFS(Detalle!$M$2:$M$326,Detalle!$T$2:$T$326,$B39,Detalle!$H$2:$H$326,$B41) | F41: =D41+E41
B42: SUMINISTRO DE MARCOS METÁLICOS DE 1.40X1.40 MTS EN ANGULO DE 1 1/2X3/16" - UND | C42: =SUMIFS(Detalle!$I$2:$I$326,Detalle!$T$2:$T$326,$B39,Detalle!$H$2:$H$326,$B42) | D42: =SUMIFS(Detalle!$K$2:$K$326,Detalle!$T$2:$T$326,$B39,Detalle!$H$2:$H$326,$B42) | E42: =SUMIFS(Detalle!$M$2:$M$326,Detalle!$T$2:$T$326,$B39,Detalle!$H$2:$H$326,$B42) | F42: =D42+E42
B43: SUMINISTRO DE TAPAS PARA CÁRCAMOS. CUARTO ELÉCTRICO. EN ANGULO DE 1 1/4X1/8" Y LAMINA ALFAJOR DE 2.5MM, PINTURA ANTICORROSIVA Y ESMALTE. - UND | C43: =SUMIFS(Detalle!$I$2:$I$326,Detalle!$T$2:$T$326,$B39,Detalle!$H$2:$H$326,$B43) | D43: =SUMIFS(Detalle!$K$2:$K$326,Detalle!$T$2:$T$326,$B39,Detalle!$H$2:$H$326,$B43) | E43: =SUMIFS(Detalle!$M$2:$M$326,Detalle!$T$2:$T$326,$B39,Detalle!$H$2:$H$326,$B43) | F43: =D43+E43
B44: SUPERBOARD ESTANDAR 1220X2440X6MM (DP) UND SUPERBOAR - UND | C44: =SUMIFS(Detalle!$I$2:$I$326,Detalle!$T$2:$T$326,$B39,Detalle!$H$2:$H$326,$B44) | D44: =SUMIFS(Detalle!$K$2:$K$326,Detalle!$T$2:$T$326,$B39,Detalle!$H$2:$H$326,$B44) | E44: =SUMIFS(Detalle!$M$2:$M$326,Detalle!$T$2:$T$326,$B39,Detalle!$H$2:$H$326,$B44) | F44: =D44+E44
B45: PERFIL RECTANGULAR DE 2"X1" X 6M CAL 18 - UND | C45: =SUMIFS(Detalle!$I$2:$I$326,Detalle!$T$2:$T$326,$B39,Detalle!$H$2:$H$326,$B45) | D45: =SUMIFS(Detalle!$K$2:$K$326,Detalle!$T$2:$T$326,$B39,Detalle!$H$2:$H$326,$B45) | E45: =SUMIFS(Detalle!$M$2:$M$326,Detalle!$T$2:$T$326,$B39,Detalle!$H$2:$H$326,$B45) | F45: =D45+E45
B46: PLATINA DE 35CMX35CMX1CM - UND | C46: =SUMIFS(Detalle!$I$2:$I$326,Detalle!$T$2:$T$326,$B39,Detalle!$H$2:$H$326,$B46) | D46: =SUMIFS(Detalle!$K$2:$K$326,Detalle!$T$2:$T$326,$B39,Detalle!$H$2:$H$326,$B46) | E46: =SUMIFS(Detalle!$M$2:$M$326,Detalle!$T$2:$T$326,$B39,Detalle!$H$2:$H$326,$B46) | F46: =D46+E46
B47: RIEL CHANNEL 4X2 RANURADO 3M - UND | C47: =SUMIFS(Detalle!$I$2:$I$326,Detalle!$T$2:$T$326,$B39,Detalle!$H$2:$H$326,$B47) | D47: =SUMIFS(Detalle!$K$2:$K$326,Detalle!$T$2:$T$326,$B39,Detalle!$H$2:$H$326,$B47) | E47: =SUMIFS(Detalle!$M$2:$M$326,Detalle!$T$2:$T$326,$B39,Detalle!$H$2:$H$326,$B47) | F47: =D47+E47
B48: MINIBREAKER BIPOLAR PARA RIEL 6AMP SIEMENS - UND | C48: =SUMIFS(Detalle!$I$2:$I$326,Detalle!$T$2:$T$326,$B39,Detalle!$H$2:$H$326,$B48) | D48: =SUMIFS(Detalle!$K$2:$K$326,Detalle!$T$2:$T$326,$B39,Detalle!$H$2:$H$326,$B48) | E48: =SUMIFS(Detalle!$M$2:$M$326,Detalle!$T$2:$T$326,$B39,Detalle!$H$2:$H$326,$B48) | F48: =D48+E48
B49: VIGUETA PARA SUPERBOARD DE 1 1/2" X3/4" CALIBRE 40 - UND | C49: =SUMIFS(Detalle!$I$2:$I$326,Detalle!$T$2:$T$326,$B39,Detalle!$H$2:$H$326,$B49) | D49: =SUMIFS(Detalle!$K$2:$K$326,Detalle!$T$2:$T$326,$B39,Detalle!$H$2:$H$326,$B49) | E49: =SUMIFS(Detalle!$M$2:$M$326,Detalle!$T$2:$T$326,$B39,Detalle!$H$2:$H$326,$B49) | F49: =D49+E49
B50: MINIBREAKER MONOPOLAR PARA RIEL 6AMP SIEMENS - UND | C50: =SUMIFS(Detalle!$I$2:$I$326,Detalle!$T$2:$T$326,$B39,Detalle!$H$2:$H$326,$B50) | D50: =SUMIFS(Detalle!$K$2:$K$326,Detalle!$T$2:$T$326,$B39,Detalle!$H$2:$H$326,$B50) | E50: =SUMIFS(Detalle!$M$2:$M$326,Detalle!$T$2:$T$326,$B39,Detalle!$H$2:$H$326,$B50) | F50: =D50+E50
B51: Cerramiento perimetral | C51: =SUMIFS(Detalle!$I$2:$I$326,Detalle!$T$2:$T$326,$B51) | D51: =SUMIFS(Detalle!$K$2:$K$326,Detalle!$T$2:$T$326,$B51) | E51: =SUMIFS(Detalle!$M$2:$M$326,Detalle!$T$2:$T$326,$B51) | F51: =D51+E51
B52: CERRAMIENTO PERIMETRAL - UND | C52: =SUMIFS(Detalle!$I$2:$I$326,Detalle!$T$2:$T$326,$B51,Detalle!$H$2:$H$326,$B52) | D52: =SUMIFS(Detalle!$K$2:$K$326,Detalle!$T$2:$T$326,$B51,Detalle!$H$2:$H$326,$B52) | E52: =SUMIFS(Detalle!$M$2:$M$326,Detalle!$T$2:$T$326,$B51,Detalle!$H$2:$H$326,$B52) | F52: =D52+E52
B53: SUMINISTRO DE PORTON METALICO MEDIDAS DE 2.38 MT x 2.40 MT. EN LAMINA GALVANIZADA CALIBRE 20, EN DOS HOJAS Y CON CHAPA ANTIPANICO. - UND | C53: =SUMIFS(Detalle!$I$2:$I$326,Detalle!$T$2:$T$326,$B51,Detalle!$H$2:$H$326,$B53) | D53: =SUMIFS(Detalle!$K$2:$K$326,Detalle!$T$2:$T$326,$B51,Detalle!$H$2:$H$326,$B53) | E53: =SUMIFS(Detalle!$M$2:$M$326,Detalle!$T$2:$T$326,$B51,Detalle!$H$2:$H$326,$B53) | F53: =D53+E53
B54: SUMINISTRO DE PORTON METALICO DE 2 MT x 2.40 MT EN LAMINA GALVANIZADA CALIBRE 20 EN 2 HOJAS Y CON CHAPA ANTIPANICO. - UND | C54: =SUMIFS(Detalle!$I$2:$I$326,Detalle!$T$2:$T$326,$B51,Detalle!$H$2:$H$326,$B54) | D54: =SUMIFS(Detalle!$K$2:$K$326,Detalle!$T$2:$T$326,$B51,Detalle!$H$2:$H$326,$B54) | E54: =SUMIFS(Detalle!$M$2:$M$326,Detalle!$T$2:$T$326,$B51,Detalle!$H$2:$H$326,$B54) | F54: =D54+E54
B55: Obra civil (concreto, agregados) | C55: =SUMIFS(Detalle!$I$2:$I$326,Detalle!$T$2:$T$326,$B55) | D55: =SUMIFS(Detalle!$K$2:$K$326,Detalle!$T$2:$T$326,$B55) | E55: =SUMIFS(Detalle!$M$2:$M$326,Detalle!$T$2:$T$326,$B55) | F55: =D55+E55
B56: CEMENTO GRIS X BULTO - UND | C56: =SUMIFS(Detalle!$I$2:$I$326,Detalle!$T$2:$T$326,$B55,Detalle!$H$2:$H$326,$B56) | D56: =SUMIFS(Detalle!$K$2:$K$326,Detalle!$T$2:$T$326,$B55,Detalle!$H$2:$H$326,$B56) | E56: =SUMIFS(Detalle!$M$2:$M$326,Detalle!$T$2:$T$326,$B55,Detalle!$H$2:$H$326,$B56) | F56: =D56+E56
B57: CRUDO DE RÍO X M3 - M3 | C57: =SUMIFS(Detalle!$I$2:$I$326,Detalle!$T$2:$T$326,$B55,Detalle!$H$2:$H$326,$B57) | D57: =SUMIFS(Detalle!$K$2:$K$326,Detalle!$T$2:$T$326,$B55,Detalle!$H$2:$H$326,$B57) | E57: =SUMIFS(Detalle!$M$2:$M$326,Detalle!$T$2:$T$326,$B55,Detalle!$H$2:$H$326,$B57) | F57: =D57+E57
...

Sheet Por proveedor
B2: GASTO POR PROVEEDOR
B3: Valores calculados con SUMAR.SI.CONJUNTO sobre la hoja Detalle.
B5: Proveedor | C5: Valor sin IVA | D5: IVA | E5: Total con IVA | F5: % del total
B6: ALURACK S.A.S. | C6: =SUMIFS(Detalle!$K$2:$K$326,Detalle!$P$2:$P$326,$B6) | D6: =SUMIFS(Detalle!$M$2:$M$326,Detalle!$P$2:$P$326,$B6) | E6: =C6+D6 | F6: =IF(SUM(Detalle!$K$2:$K$326)=0,0,C6/SUM(Detalle!$K$2:$K$326))
B7: INGENIERIA Y SOLUCIONES DE NARIÑO SAS | C7: =SUMIFS(Detalle!$K$2:$K$326,Detalle!$P$2:$P$326,$B7) | D7: =SUMIFS(Detalle!$M$2:$M$326,Detalle!$P$2:$P$326,$B7) | E7: =C7+D7 | F7: =IF(SUM(Detalle!$K$2:$K$326)=0,0,C7/SUM(Detalle!$K$2:$K$326))
B8: ELECTRICOS DEL VALLE SAS | C8: =SUMIFS(Detalle!$K$2:$K$326,Detalle!$P$2:$P$326,$B8) | D8: =SUMIFS(Detalle!$M$2:$M$326,Detalle!$P$2:$P$326,$B8) | E8: =C8+D8 | F8: =IF(SUM(Detalle!$K$2:$K$326)=0,0,C8/SUM(Detalle!$K$2:$K$326))
B9: GRUPO SOLAIRE SAS | C9: =SUMIFS(Detalle!$K$2:$K$326,Detalle!$P$2:$P$326,$B9) | D9: =SUMIFS(Detalle!$M$2:$M$326,Detalle!$P$2:$P$326,$B9) | E9: =C9+D9 | F9: =IF(SUM(Detalle!$K$2:$K$326)=0,0,C9/SUM(Detalle!$K$2:$K$326))
B10: CAMPO HELMER PORTILLO PORTILLA | C10: =SUMIFS(Detalle!$K$2:$K$326,Detalle!$P$2:$P$326,$B10) | D10: =SUMIFS(Detalle!$M$2:$M$326,Detalle!$P$2:$P$326,$B10) | E10: =C10+D10 | F10: =IF(SUM(Detalle!$K$2:$K$326)=0,0,C10/SUM(Detalle!$K$2:$K$326))
B11: FAINCO SAS | C11: =SUMIFS(Detalle!$K$2:$K$326,Detalle!$P$2:$P$326,$B11) | D11: =SUMIFS(Detalle!$M$2:$M$326,Detalle!$P$2:$P$326,$B11) | E11: =C11+D11 | F11: =IF(SUM(Detalle!$K$2:$K$326)=0,0,C11/SUM(Detalle!$K$2:$K$326))
B12: HUMBERTO JAVIER ROSERO POTOSI | C12: =SUMIFS(Detalle!$K$2:$K$326,Detalle!$P$2:$P$326,$B12) | D12: =SUMIFS(Detalle!$M$2:$M$326,Detalle!$P$2:$P$326,$B12) | E12: =C12+D12 | F12: =IF(SUM(Detalle!$K$2:$K$326)=0,0,C12/SUM(Detalle!$K$2:$K$326))
B13: MAYERLINE TOBAR GOMEZ | C13: =SUMIFS(Detalle!$K$2:$K$326,Detalle!$P$2:$P$326,$B13) | D13: =SUMIFS(Detalle!$M$2:$M$326,Detalle!$P$2:$P$326,$B13) | E13: =C13+D13 | F13: =IF(SUM(Detalle!$K$2:$K$326)=0,0,C13/SUM(Detalle!$K$2:$K$326))
B14: ANDREA PATRICIA LASSO (FERROPAISA) | C14: =SUMIFS(Detalle!$K$2:$K$326,Detalle!$P$2:$P$326,$B14) | D14: =SUMIFS(Detalle!$M$2:$M$326,Detalle!$P$2:$P$326,$B14) | E14: =C14+D14 | F14: =IF(SUM(Detalle!$K$2:$K$326)=0,0,C14/SUM(Detalle!$K$2:$K$326))
B15: JASSON ALBEIRO VALENCIA ROSERO | C15: =SUMIFS(Detalle!$K$2:$K$326,Detalle!$P$2:$P$326,$B15) | D15: =SUMIFS(Detalle!$M$2:$M$326,Detalle!$P$2:$P$326,$B15) | E15: =C15+D15 | F15: =IF(SUM(Detalle!$K$2:$K$326)=0,0,C15/SUM(Detalle!$K$2:$K$326))
B16: DILIANA HINOJOSA INFANTE (DISTRIBUIDORA DE MATERIALES DYD) | C16: =SUMIFS(Detalle!$K$2:$K$326,Detalle!$P$2:$P$326,$B16) | D16: =SUMIFS(Detalle!$M$2:$M$326,Detalle!$P$2:$P$326,$B16) | E16: =C16+D16 | F16: =IF(SUM(Detalle!$K$2:$K$326)=0,0,C16/SUM(Detalle!$K$2:$K$326))
B17: DAGELEC LTDA | C17: =SUMIFS(Detalle!$K$2:$K$326,Detalle!$P$2:$P$326,$B17) | D17: =SUMIFS(Detalle!$M$2:$M$326,Detalle!$P$2:$P$326,$B17) | E17: =C17+D17 | F17: =IF(SUM(Detalle!$K$2:$K$326)=0,0,C17/SUM(Detalle!$K$2:$K$326))
... B38: SEGURIDAD DEL SUR LIMITADA | C38: =SUMIFS(Detalle!$K$2:$K$326,Detalle!$P$2:$P$326,$B38) | D38: =SUMIFS(Detalle!$M$2:$M$326,Detalle!$P$2:$P$326,$B38) | E38: =C38+D38 | F38: =IF(SUM(Detalle!$K$2:$K$326)=0,0,C38/SUM(Detalle!$K$2:$K$326))
B39: TOTAL | C39: =SUM(Detalle!$K$2:$K$326) | D39: =SUM(Detalle!$M$2:$M$326) | E39: =C39+D39 | F39: 1

Sheet Por estado
B2: COMPRAS POR ESTADO Y LEGALIZACIÓN
B4: Por estado de la orden | E4: Por estado de legalización
B5: Concepto | C5: Valor sin IVA | E5: Concepto | F5: Valor sin IVA
B6: CERRADA | C6: =SUMIFS(Detalle!$K$2:$K$326,Detalle!$D$2:$D$326,B6) | E6: PAGADA | F6: =SUMIFS(Detalle!$K$2:$K$326,Detalle!$E$2:$E$326,E6)
B7: GENERADA | C7: =SUMIFS(Detalle!$K$2:$K$326,Detalle!$D$2:$D$326,B7) | E7: CAUSADA | F7: =SUMIFS(Detalle!$K$2:$K$326,Detalle!$E$2:$E$326,E7)
B8: TOTAL | C8: =SUM(C6:C7) | E8: PENDIENTE | F8: =SUMIFS(Detalle!$K$2:$K$326,Detalle!$E$2:$E$326,E8)
E9: TOTAL | F9: =SUM(F6:F8)
B12: Por tipo de solicitud
B13: Concepto | C13: Valor sin IVA
B14: PLANEADA | C14: =SUMIFS(Detalle!$K$2:$K$326,Detalle!$Q$2:$Q$326,B14)
B15: URGENCIA | C15: =SUMIFS(Detalle!$K$2:$K$326,Detalle!$Q$2:$Q$326,B15)
B16: EMERGENCIA | C16: =SUMIFS(Detalle!$K$2:$K$326,Detalle!$Q$2:$Q$326,B16)
B17: TOTAL | C17: =SUM(C14:C16)

Sheet Detalle
A1: Fecha | B1: No OC | C1: No pedido | D1: Estado | E1: Legalización | F1: Grupo | G1: Sub grupo | H1: Producto / servicio | I1: Cant. | J1: Precio unit. | K1: Valor sin IVA | L1: Tipo impuesto | M1: IVA | N1: Total con IVA | O1: Solicitó | P1: Proveedor | Q1: Tipo solicitud | R1: Tipo proyecto | S1: No factura | T1: Categoría de ítem
A2: 46259.466 | B2: 3975 | C2: 3083 | D2: CERRADA | E2: PAGADA | F2: Servicio | G2: Retie | H2: CORTE EN ACRILICO - UND | I2: 1 | J2: 1554400 | K2: 1554400 | M2: 0 | N2: =K2+M2 | O2: LAURA SOFIA SALAS ROSERO | P2: ANGELICA MARIA AGREDA AGREDA | Q2: PLANEADA | R2: MINI GRANJAS | S2: FE1592 | T2: Servicios de obra e ingeniería
A3: 46259.465 | B3: 3973 | C3: 3078 | D3: CERRADA | E3: PAGADA | F3: Servicio | G3: Retie | H3: CORTE EN ACRILICO - UND | I3: 1 | J3: 114000 | K3: 114000 | M3: 0 | N3: =K3+M3 | O3: LAURA SOFIA SALAS ROSERO | P3: ANGELICA MARIA AGREDA AGREDA | Q3: PLANEADA | R3: MINI GRANJAS | S3: FE1607 | T3: Servicios de obra e ingeniería
A4: 46259.464 | B4: 3972 | C4: 3075 | D4: CERRADA | E4: PAGADA | F4: Servicio | G4: Retie | H4: CORTE EN ACRILICO - UND | I4: 1 | J4: 178000 | K4: 178000 | M4: 0 | N4: =K4+M4 | O4: LAURA SOFIA SALAS ROSERO | P4: ANGELICA MARIA AGREDA AGREDA | Q4: PLANEADA | R4: MINI GRANJAS | S4: FE1613 | T4: Servicios de obra e ingeniería
A5: 46258.516 | B5: 3961 | C5: 3060 | D5: CERRADA | E5: PAGADA | F5: Servicio | G5: Retie | H5: CORTE EN ACRILICO - UND | I5: 1 | J5: 63400 | K5: 63400 | M5: 0 | N5: =K5+M5 | O5: LAURA SOFIA SALAS ROSERO | P5: ANGELICA MARIA AGREDA AGREDA | Q5: PLANEADA | R5: MINI GRANJAS | S5: FACTURA ELECTRONICA DE VENTA FE 1632 | T5: Servicios de obra e ingeniería
A6: 46248.669 | B6: 3866 | C6: 2986 | D6: CERRADA | E6: PAGADA | F6: Servicio | G6: Baños Portátiles | H6: ALQUILER DE BAÑO PORTATIL - UND | I6: 1 | J6: 1721600 | K6: 1721600 | M6: 0 | N6: =K6+M6 | O6: LAURA SOFIA SALAS ROSERO | P6: HOOVER ANTONIO GUACHAVES LASSO | Q6: PLANEADA | R6: MINI GRANJAS | S6: Número de Factura: FEV-115 | T6: Baños y sanitarios portátiles
A7: 46248.667 | B7: 3860 | C7: 2946 | D7: CERRADA | E7: CAUSADA | F7: Servicio | G7: Preparativos Previos Inicio De Obras | H7: EXAMEN PERIODICO - UND | I7: 1 | J7: 32000 | K7: 32000 | M7: 0 | N7: =K7+M7 | O7: LAURA SOFIA SALAS ROSERO | P7: IPS BIENESTAR LABORAL SAS | Q7: URGENCIA | R7: MINI GRANJAS | S7: N 4417 | T7: SST y exámenes médicos
A8: 46237.455 | B8: 3697 | C8: 2812 | D8: CERRADA | E8: PAGADA | F8: Servicio | G8: Logística Viáticos | H8: SERVICIO DE RESTAURANTE - UND | I8: 39 | J8: 10362.69 | K8: 404144.91 | M8: 0 | N8: =K8+M8 | O8: LAURA SOFIA SALAS ROSERO | P8: MAYERLINE TOBAR GOMEZ | Q8: PLANEADA | R8: MINI GRANJAS | S8: FE 1876 | T8: Viáticos - Alimentación
A9: 46237.455 | B9: 3697 | C9: 2812 | D9: CERRADA | E9: PAGADA | F9: Servicio | G9: Logística Viáticos | H9: SERVICIO DE RESTAURANTE - UND | I9: 69 | J9: 13471.51 | K9: 929534.19 | M9: 0 | N9: =K9+M9 | O9: LAURA SOFIA SALAS ROSERO | P9: MAYERLINE TOBAR GOMEZ | Q9: PLANEADA | R9: MINI GRANJAS | S9: FE 1876 | T9: Viáticos - Alimentación
A10: 46234.376 | B10: 3672 | C10: 2747 | D10: CERRADA | E10: PAGADA | F10: Servicio | G10: Logística Viáticos | H10: SERVICIO DE HOTEL - UND | I10: 11 | J10: 36270 | K10: 398970 | M10: 0 | N10: =K10+M10 | O10: LAURA SOFIA SALAS ROSERO | P10: MAYERLINE TOBAR GOMEZ | Q10: PLANEADA | R10: MINI GRANJAS | S10: FE 1884 | T10: Viáticos - Hospedaje
A11: 46234.376 | B11: 3672 | C11: 2747 | D11: CERRADA | E11: PAGADA | F11: Servicio | G11: Logística Viáticos | H11: SERVICIO DE HOTEL - UND | I11: 1 | J11: 621762 | K11: 621762 | M11: 0 | N11: =K11+M11 | O11: LAURA SOFIA SALAS ROSERO | P11: MAYERLINE TOBAR GOMEZ | Q11: PLANEADA | R11: MINI GRANJAS | S11: FE 1884 | T11: Viáticos - Hospedaje
A12: 46225.596 | B12: 3556 | C12: 2705 | D12: CERRADA | E12: PAGADA | F12: Servicio | G12: Baños Portátiles | H12: ALQUILER DE BAÑO PORTATIL - UND | I12: 1 | J12: 1721600 | K12: 1721600 | M12: 0 | N12: =K12+M12 | O12: LAURA SOFIA SALAS ROSERO | P12: HOOVER ANTONIO GUACHAVES LASSO | Q12: URGENCIA | R12: MINI GRANJAS | S12: FEV 101 | T12: Baños y sanitarios portátiles
A13: 46220.442 | B13: 3533 | C13: 2673 | D13: CERRADA | E13: CAUSADA | F13: Servicio | G13: Set (Electrico)Servicio | H13: PRUEBAS DE RUTINA EN SITIO A SISTEMAS DE MEDICION NIVEL 2 PARA TC´s Y TP´s - UND | I13: 1 | J13: 5880000 | K13: 5880000 | L13: IVA 19% | M13: 1117200 | N13: =K13+M13 | O13: LAURA SOFIA SALAS ROSERO | P13: NEGAWATT S.A.S | Q13: PLANEADA | R13: MINI GRANJAS | S13: COT-479 | T13: RETIE / Legalización / Medición
A14: 46211.68 | B14: 3440 | C14: 2614 | D14: CERRADA | E14: PAGADA | F14: Servicio | G14: Logística Viáticos | H14: SERVICIO DE RESTAURANTE - UND | I14: 31 | J14: 10362.69 | K14: 321243.39 | M14: 0 | N14: =K14+M14 | O14: LAURA SOFIA SALAS ROSERO | P14: MAYERLINE TOBAR GOMEZ | Q14: PLANEADA | R14: MINI GRANJAS | S14: FE1841 | T14: Viáticos - Alimentación
A15: 46211.68 | B15: 3440 | C15: 2614 | D15: CERRADA | E15: PAGADA | F15: Servicio | G15: Logística Viáticos | H15: SERVICIO DE RESTAURANTE - UND | I15: 61 | J15: 13471.51 | K15: 821762.11 | M15: 0 | N15: =K15+M15 | O15: LAURA SOFIA SALAS ROSERO | P15: MAYERLINE TOBAR GOMEZ | Q15: PLANEADA | R15: MINI GRANJAS | S15: FE1841 | T15: Viáticos - Alimentación
A16: 46205.474 | B16: 3414 | C16: 2579 | D16: CERRADA | E16: PAGADA | F16: Servicio | G16: Logística Viáticos | H16: SERVICIO DE COMEDOR / RESTAURANTE - UND | I16: 36 | J16: 10362.69 | K16: 373056.84 | M16: 0 | N16: =K16+M16 | O16: LAURA SOFIA SALAS ROSERO | P16: MAYERLINE TOBAR GOMEZ | Q16: PLANEADA | R16: MINI GRANJAS | S16: FE1818 | T16: Viáticos - Alimentación
A17: 46205.474 | B17: 3414 | C17: 2579 | D17: CERRADA | E17: PAGADA | F17: Servicio | G17: Logística Viáticos | H17: SERVICIO DE RESTAURANTE - UND | I17: 70 | J17: 13471.51 | K17: 943005.7 | M17: 0 | N17: =K17+M17 | O17: LAURA SOFIA SALAS ROSERO | P17: MAYERLINE TOBAR GOMEZ | Q17: PLANEADA | R17: MINI GRANJAS | S17: FE1818 | T17: Viáticos - Alimentación
A18: 46205.455 | B18: 3409 | C18: 2581 | D18: CERRADA | E18: PAGADA | F18: Servicio | G18: Logística Viáticos | H18: SERVICIO DE HOTEL - UND | I18: 3 | J18: 518134.72 | K18: 1554404.2 | M18: 0 | N18: =K18+M18 | O18: LAURA SOFIA SALAS ROSERO | P18: MAYERLINE TOBAR GOMEZ | Q18: PLANEADA | R18: MINI GRANJAS | S18: FE1832 | T18: Viáticos - Hospedaje
A19: 46192.389 | B19: 3330 | C19: 2502 | D19: CERRADA | E19: PAGADA | F19: C. Canalizaciones | G19: Instalación De Tuberías Ac, Dc Y Tierra | H19: CURVA 1" PVC NACIONAL CONDUIT (90°/1 CAMPANA)- TUBOSA/IMEC 1302-160807 - UND | I19: 30 | J19: 1058.7 | K19: 31761 | L19: IVA 19% | M19: 6034 | N19: =K19+M19 | O19: LAURA SOFIA SALAS ROSERO | P19: ELECTRICOS DEL VALLE SAS | Q19: EMERGENCIA | R19: MINI GRANJAS | S19: EPE25355 | T19: Canalización y tubería
A20: 46192.389 | B20: 3330 | C20: 2502 | D20: CERRADA | E20: PAGADA | F20: C. Canalizaciones | G20: Instalación De Tuberías Ac, Dc Y Tierra | H20: CAPACETE 1" IMC GALVANIZADO E.V SOLUTIONS - UND | I20: 8 | J20: 3645.1 | K20: 29160.8 | L20: IVA 19% | M20: 5540 | N20: =K20+M20 | O20: LAURA SOFIA SALAS ROSERO | P20: ELECTRICOS DEL VALLE SAS | Q20: EMERGENCIA | R20: MINI GRANJAS | S20: EPE25355 | T20: Otros / sin clasificar
A21: 46192.389 | B21: 3330 | C21: 2502 | D21: CERRADA | E21: PAGADA | F21: C. Canalizaciones | G21: Instalación De Tuberías Ac, Dc Y Tierra | H21: TUBO 1" PVC COUNDUIT 3 MTS 1302-160905 - UND | I21: 110 | J21: 5840.4 | K21: 642444 | L21: IVA 19% | M21: 122064 | N21: =K21+M21 | O21: LAURA SOFIA SALAS ROSERO | P21: ELECTRICOS DEL VALLE SAS | Q21: EMERGENCIA | R21: MINI GRANJAS | S21: EPE25355 | T21: Canalización y tubería
A22: 46192.389 | B22: 3330 | C22: 2502 | D22: CERRADA | E22: PAGADA | F22: C. Canalizaciones | G22: Instalación De Tuberías Ac, Dc Y Tierra | H22: TUBO 1" IMC GALV 3MTS 1301-160693 - UND | I22: 8 | J22: 29341.6 | K22: 234732.8 | L22: IVA 19% | M22: 44599 | N22: =K22+M22 | O22: LAURA SOFIA SALAS ROSERO | P22: ELECTRICOS DEL VALLE SAS | Q22: EMERGENCIA | R22: MINI GRANJAS | S22: EPE25355 | T22: Canalización y tubería
A23: 46183.52 | B23: 3242 | C23: 2449 | D23: CERRADA | E23: PAGADA | F23: Montaje Eléctrico | G23: Set (Electrico)Servicio | H23: DESCARGUE E INSTALACION DE CELDAS PARA TRANSFORMADORES MAS SERVICIO DE GRUA - UND | I23: 1 | J23: 1528000 | K23: 1528000 | M23: 0 | N23: =K23+M23 | O23: LAURA SOFIA SALAS ROSERO | P23: JOHN JAIRO CHAPAL ESTACIO | Q23: PLANEADA | R23: MINI GRANJAS | S23: FE-820 | T23: Fletes y transporte de carga
A24: 46183.518 | B24: 3238 | C24: 2419 | D24: CERRADA | E24: PAGADA | F24: Servicio | G24: Logística Viáticos | H24: SERVICIO DE RESTAURANTE - UND | I24: 45 | J24: 10362.69 | K24: 466321.05 | M24: 0 | N24: =K24+M24 | O24: LAURA SOFIA SALAS ROSERO | P24: MAYERLINE TOBAR GOMEZ | Q24: PLANEADA | R24: MINI GRANJAS | S24: 1781 | T24: Viáticos - Alimentación
A25: 46183.518 | B25: 3238 | C25: 2419 | D25: CERRADA | E25: PAGADA | F25: Servicio | G25: Logística Viáticos | H25: SERVICIO DE RESTAURANTE - UND | I25: 83 | J25: 13471.51 | K25: 1118135.3 | M25: 0 | N25: =K25+M25 | O25: LAURA SOFIA SALAS ROSERO | P25: MAYERLINE TOBAR GOMEZ | Q25: PLANEADA | R25: MINI GRANJAS | S25: 1781 | T25: Viáticos - Alimentación
A26: 46183.518 | B26: 3237 | C26: 2421 | D26: CERRADA | E26: PAGADA | F26: Set (Civil) Suministro | G26: Set (Civil) Servicio | H26: RECEBO - M3 | I26: 14 | J26: 85000 | K26: 1190000 | M26: 0 | N26: =K26+M26 | O26: LAURA SOFIA SALAS ROSERO | P26: CAMPO HELMER PORTILLO PORTILLA | Q26: PLANEADA | R26: MINI GRANJAS | S26: 0255 | T26: Obra civil (concreto, agregados)
A27: 46183.518 | B27: 3237 | C27: 2421 | D27: CERRADA | E27: PAGADA | F27: Servicio | G27: Preparativos Previos Inicio De Obras | H27: ARENA DE RIO METRO CUBICO - UND | I27: 7 | J27: 90000 | K27: 630000 | M27: 0 | N27: =K27+M27 | O27: LAURA SOFIA SALAS ROSERO | P27: CAMPO HELMER PORTILLO PORTILLA | Q27: PLANEADA | R27: MINI GRANJAS | S27: 0255 | T27: Obra civil (concreto, agregados)
A28: 46178.441 | B28: 3190 | C28: 2385 | D28: CERRADA | E28: PAGADA | F28: Servicio | G28: Logística Viáticos | H28: SERVICIO DE HOTEL - UND | I28: 3 | J28: 518135 | K28: 1554405 | M28: 0 | N28: =K28+M28 | O28: LAURA SOFIA SALAS ROSERO | P28: MAYERLINE TOBAR GOMEZ | Q28: PLANEADA | R28: MINI GRANJAS | S28: 1744 | T28: Viáticos - Hospedaje
A29: 46170.629 | B29: 3128 | C29: 2331 | D29: GENERADA | E29: PENDIENTE | F29: Set (Electrico) Suministro | G29: Set (Electrico)Servicio | H29: SERVICIO DE TRANSPORTE - UND | I29: 1 | J29: 16806 | K29: 16806 | L29: IVA 19% | M29: 3193 | N29: =K29+M29 | O29: LAURA SOFIA SALAS ROSERO | P29: HUMBERTO JAVIER ROSERO POTOSI | Q29: PLANEADA | R29: MINI GRANJAS | T29: Viáticos - Transporte
A30: 46170.629 | B30: 3128 | C30: 2331 | D30: GENERADA | E30: PENDIENTE | F30: Set (Electrico) Suministro | G30: Set (Electrico)Servicio | H30: SUMINISTRO DE TAPA METÁLICA DE 0.25 X 0.28 MTS PARA CAJA DE INSPECCIÓN EN LÁMINA ALFAJOR DE 2.5MM, ANGULO DE 1 1/2X3/16, PINTURA ANTICORROSIVA Y ESMALTE. - UND | I30: 2 | J30: 96639 | K30: 193278 | L30: IVA 19% | M30: 36722 | N30: =K30+M30 | O30: LAURA SOFIA SALAS ROSERO | P30: HUMBERTO JAVIER ROSERO POTOSI | Q30: PLANEADA | R30: MINI GRANJAS | T30: RETIE / Legalización / Medición
A31: 46170.628 | B31: 3127 | C31: 2348 | D31: CERRADA | E31: CAUSADA | F31: Cajas De Paso | G31: Transportes | H31: SERVICIO DE TRANSPORTE - UND | I31: 1 | J31: 50000 | K31: 50000 | M31: 0 | N31: =K31+M31 | O31: LAURA SOFIA SALAS ROSERO | P31: HUMBERTO JAVIER ROSERO POTOSI | Q31: PLANEADA | R31: MINI GRANJAS | S31: FEHJ 36 | T31: Viáticos - Transporte
A32: 46170.628 | B32: 3127 | C32: 2348 | D32: CERRADA | E32: CAUSADA | F32: Cajas De Paso | G32: (Sin Subgrupo) | H32: SUMINISTRO DE MARCOS METÁLICOS PARA CAJA DE INSPECCIÓN , PINTURA ANTICORROSIVA Y ESMALTE NEGRO EN ÁNGULO 1 1/2X3/16" CON DIMENSIONES: ANCHO: 1.5 M - LARGO: 1.5 M - UND | I32: 1 | J32: 162185 | K32: 162185 | L32: IVA 19% | M32: 30815 | N32: =K32+M32 | O32: LAURA SOFIA SALAS ROSERO | P32: HUMBERTO JAVIER ROSERO POTOSI | Q32: PLANEADA | R32: MINI GRANJAS | S32: FEHJ 36 | T32: RETIE / Legalización / Medición
A33: 46170.628 | B33: 3127 | C33: 2348 | D33: CERRADA | E33: CAUSADA | F33: Cajas De Paso | G33: (Sin Subgrupo) | H33: SUMINISTRO DE TAPAS METÁLICAS PARA CAJA DE INSPECCIÓN EN LÁMINA ALFAJOR DE 2.5 MM, ÁNGULO DE 1 ½ X 3/16", PINTURA ANTICORROSIVA Y ESMALTE. DIMENSIONES: ANCHO: 1.5M Y LARGO: 1.5M - UND | I33: 1 | J33: 794118 | K33: 794118 | L33: IVA 19% | M33: 150882 | N33: =K33+M33 | O33: LAURA SOFIA SALAS ROSERO | P33: HUMBERTO JAVIER ROSERO POTOSI | Q33: PLANEADA | R33: MINI GRANJAS | S33: FEHJ 36 | T33: RETIE / Legalización / Medición
A34: 46170.621 | B34: 3119 | C34: 2328 | D34: CERRADA | E34: PAGADA | F34: Servicio | G34: Logística Viáticos | H34: SERVICIO DE RESTAURANTE - UND | I34: 38 | J34: 10362.7 | K34: 393782.6 | M34: 0 | N34: =K34+M34 | O34: LAURA SOFIA SALAS ROSERO | P34: MAYERLINE TOBAR GOMEZ | Q34: URGENCIA | R34: MINI GRANJAS | S34: 1728 | T34: Viáticos - Alimentación
A35: 46170.621 | B35: 3119 | C35: 2328 | D35: CERRADA | E35: PAGADA | F35: Servicio | G35: Logística Viáticos | H35: SERVICIO DE RESTAURANTE - UND | I35: 68 | J35: 13471.5 | K35: 916062 | M35: 0 | N35: =K35+M35 | O35: LAURA SOFIA SALAS ROSERO | P35: MAYERLINE TOBAR GOMEZ | Q35: URGENCIA | R35: MINI GRANJAS | S35: 1728 | T35: Viáticos - Alimentación
A36: 46156.703 | B36: 2943 | C36: 2207 | D36: CERRADA | E36: PAGADA | F36: 9-Legalización | G36: 9.1 -Retie Gd | H36: CERTIFICADO RETIE - UND | I36: 1 | J36: 1000000 | K36: 1000000 | L36: IVA 19% | M36: 190000 | N36: =K36+M36 | O36: LAURA SOFIA SALAS ROSERO | P36: ODIR CERTIFICACIONES SAS | Q36: EMERGENCIA | R36: MINI GRANJAS | S36: ODIR-016201 | T36: RETIE / Legalización / Medición
A37: 46155.427 | B37: 2925 | C37: 2159 | D37: CERRADA | E37: PAGADA | F37: Set (Electrico) Suministro | G37: (Sin Subgrupo) | H37: SENSOR DE HUMO LYNX SECURITY LY-DH4T - UND | I37: 2 | J37: 58000 | K37: 116000 | L37: IVA 19% | M37: 22040 | N37: =K37+M37 | O37: LAURA SOFIA SALAS ROSERO | P37: SEGURIDAD DEL SUR LIMITADA | Q37: PLANEADA | R37: MINI GRANJAS | S37: 002 | T37: Otros / sin clasificar
A38: 46155.426 | B38: 2924 | C38: 2159 | D38: CERRADA | E38: CAUSADA | F38: Set (Electrico) Suministro | G38: (Sin Subgrupo) | H38: EXTINTOR TIPO CO2 CLASE BC X 10LB (ACERO) - UND | I38: 2 | J38: 250000 | K38: 500000 | L38: IVA 19% | M38: 95000 | N38: =K38+M38 | O38: LAURA SOFIA SALAS ROSERO | P38: DISTRITO E SAS | Q38: PLANEADA | R38: MINI GRANJAS | S38: 2155 | T38: Otros / sin clasificar
A39: 46155.42 | B39: 2919 | C39: 2164 | D39: CERRADA | E39: PAGADA | F39: Servicio | G39: Logística Viáticos | H39: SERVICIO DE RESTAURANTE - UND | I39: 38 | J39: 10362.69 | K39: 393782.22 | M39: 0 | N39: =K39+M39 | O39: LAURA SOFIA SALAS ROSERO | P39: MAYERLINE TOBAR GOMEZ | Q39: PLANEADA | R39: MINI GRANJAS | S39: 1709 | T39: Viáticos - Alimentación
A40: 46155.42 | B40: 2919 | C40: 2164 | D40: CERRADA | E40: PAGADA | F40: Servicio | G40: Logística Viáticos | H40: SERVICIO DE RESTAURANTE - UND | I40: 67 | J40: 13471.51 | K40: 902591.17 | M40: 0 | N40: =K40+M40 | O40: LAURA SOFIA SALAS ROSERO | P40: MAYERLINE TOBAR GOMEZ | Q40: PLANEADA | R40: MINI GRANJAS | S40: 1709 | T40: Viáticos - Alimentación
...
